2023-09-24 00:29:32,809 INFO    StreamThr :805 [internal.py:wandb_internal():86] W&B internal server running at pid: 805, started at: 2023-09-24 00:29:32.808048
2023-09-24 00:29:32,810 DEBUG   HandlerThread:805 [handler.py:handle_request():144] handle_request: status
2023-09-24 00:29:32,812 INFO    WriterThread:805 [datastore.py:open_for_write():85] open: /mnt/d/PROJECTION/TianChi/STS-2D/wandb/run-20230924_002932-4tqudvuc/run-4tqudvuc.wandb
2023-09-24 00:29:32,821 DEBUG   SenderThread:805 [sender.py:send():369] send: header
2023-09-24 00:29:32,821 DEBUG   SenderThread:805 [sender.py:send():369] send: run
2023-09-24 00:29:34,435 INFO    SenderThread:805 [dir_watcher.py:__init__():211] watching files in: /mnt/d/PROJECTION/TianChi/STS-2D/wandb/run-20230924_002932-4tqudvuc/files
2023-09-24 00:29:34,436 DEBUG   HandlerThread:805 [handler.py:handle_request():144] handle_request: check_version
2023-09-24 00:29:34,446 INFO    SenderThread:805 [sender.py:_start_run_threads():1100] run started: 4tqudvuc with start time 1695486572.807259
2023-09-24 00:29:34,447 DEBUG   SenderThread:805 [sender.py:send_request():396] send_request: summary_record
2023-09-24 00:29:34,451 INFO    SenderThread:805 [sender.py:_save_file():1354] saving file wandb-summary.json with policy end
2023-09-24 00:29:34,452 DEBUG   SenderThread:805 [sender.py:send_request():396] send_request: check_version
2023-09-24 00:29:35,050 DEBUG   HandlerThread:805 [handler.py:handle_request():144] handle_request: run_start
2023-09-24 00:29:35,057 ERROR   HandlerThread:805 [gpu.py:is_available():381] Error initializing NVML: The operating system has blocked the request.
2023-09-24 00:29:35,058 DEBUG   HandlerThread:805 [system_info.py:__init__():31] System info init
2023-09-24 00:29:35,058 DEBUG   HandlerThread:805 [system_info.py:__init__():46] System info init done
2023-09-24 00:29:35,058 INFO    HandlerThread:805 [system_monitor.py:start():181] Starting system monitor
2023-09-24 00:29:35,058 INFO    SystemMonitor:805 [system_monitor.py:_start():145] Starting system asset monitoring threads
2023-09-24 00:29:35,058 INFO    HandlerThread:805 [system_monitor.py:probe():201] Collecting system info
2023-09-24 00:29:35,059 INFO    SystemMonitor:805 [interfaces.py:start():190] Started cpu monitoring
2023-09-24 00:29:35,061 INFO    SystemMonitor:805 [interfaces.py:start():190] Started disk monitoring
2023-09-24 00:29:35,061 INFO    SystemMonitor:805 [interfaces.py:start():190] Started memory monitoring
2023-09-24 00:29:35,062 INFO    SystemMonitor:805 [interfaces.py:start():190] Started network monitoring
2023-09-24 00:29:35,063 DEBUG   HandlerThread:805 [system_info.py:probe():195] Probing system
2023-09-24 00:29:35,093 DEBUG   HandlerThread:805 [gitlib.py:_init_repo():53] git repository is invalid
2023-09-24 00:29:35,093 DEBUG   HandlerThread:805 [system_info.py:probe():240] Probing system done
2023-09-24 00:29:35,093 DEBUG   HandlerThread:805 [system_monitor.py:probe():210] {'os': 'Linux-5.10.16.3-microsoft-standard-WSL2-x86_64-with-glibc2.35', 'python': '3.9.16', 'heartbeatAt': '2023-09-23T16:29:35.063923', 'startedAt': '2023-09-23T16:29:32.748355', 'docker': None, 'cuda': None, 'args': ('wandb', 'login'), 'state': 'running', 'program': '/mnt/d/PROJECTION/TianChi/STS-2D/train.py', 'codePath': 'train.py', 'host': 'DESKTOP-LT0ASMB', 'username': 'zy', 'executable': '/home/zy/anaconda3/envs/kaggle_torch/bin/python3', 'cpu_count': 3, 'cpu_count_logical': 5, 'cpu_freq': {'current': 3192.008, 'min': 0.0, 'max': 0.0}, 'cpu_freq_per_core': [{'current': 3192.008, 'min': 0.0, 'max': 0.0}, {'current': 3192.008, 'min': 0.0, 'max': 0.0}, {'current': 3192.008, 'min': 0.0, 'max': 0.0}, {'current': 3192.008, 'min': 0.0, 'max': 0.0}, {'current': 3192.008, 'min': 0.0, 'max': 0.0}], 'disk': {'total': 250.98248672485352, 'used': 63.60935974121094}, 'memory': {'total': 24.93661880493164}}
2023-09-24 00:29:35,094 INFO    HandlerThread:805 [system_monitor.py:probe():211] Finished collecting system info
2023-09-24 00:29:35,094 INFO    HandlerThread:805 [system_monitor.py:probe():214] Publishing system info
2023-09-24 00:29:35,094 DEBUG   HandlerThread:805 [system_info.py:_save_pip():51] Saving list of pip packages installed into the current environment
2023-09-24 00:29:35,125 DEBUG   HandlerThread:805 [system_info.py:_save_pip():67] Saving pip packages done
2023-09-24 00:29:35,126 DEBUG   HandlerThread:805 [system_info.py:_save_conda():74] Saving list of conda packages installed into the current environment
2023-09-24 00:29:35,155 ERROR   HandlerThread:805 [system_info.py:_save_conda():85] Error saving conda packages: [Errno 2] No such file or directory: 'conda'
Traceback (most recent call last):
  File "/home/zy/anaconda3/envs/kaggle_torch/lib/python3.9/site-packages/wandb/sdk/internal/system/system_info.py", line 81, in _save_conda
    subprocess.call(
  File "/home/zy/anaconda3/envs/kaggle_torch/lib/python3.9/subprocess.py", line 349, in call
    with Popen(*popenargs, **kwargs) as p:
  File "/home/zy/anaconda3/envs/kaggle_torch/lib/python3.9/subprocess.py", line 951, in __init__
    self._execute_child(args, executable, preexec_fn, close_fds,
  File "/home/zy/anaconda3/envs/kaggle_torch/lib/python3.9/subprocess.py", line 1821, in _execute_child
    raise child_exception_type(errno_num, err_msg, err_filename)
FileNotFoundError: [Errno 2] No such file or directory: 'conda'
2023-09-24 00:29:35,156 DEBUG   HandlerThread:805 [system_info.py:_save_conda():86] Saving conda packages done
2023-09-24 00:29:35,158 INFO    HandlerThread:805 [system_monitor.py:probe():216] Finished publishing system info
2023-09-24 00:29:35,164 DEBUG   SenderThread:805 [sender.py:send():369] send: files
2023-09-24 00:29:35,165 INFO    SenderThread:805 [sender.py:_save_file():1354] saving file wandb-metadata.json with policy now
2023-09-24 00:29:35,171 DEBUG   HandlerThread:805 [handler.py:handle_request():144] handle_request: stop_status
2023-09-24 00:29:35,173 DEBUG   SenderThread:805 [sender.py:send_request():396] send_request: stop_status
2023-09-24 00:29:35,442 INFO    Thread-12 :805 [dir_watcher.py:_on_file_created():272] file/dir created: /mnt/d/PROJECTION/TianChi/STS-2D/wandb/run-20230924_002932-4tqudvuc/files/requirements.txt
2023-09-24 00:29:35,443 INFO    Thread-12 :805 [dir_watcher.py:_on_file_created():272] file/dir created: /mnt/d/PROJECTION/TianChi/STS-2D/wandb/run-20230924_002932-4tqudvuc/files/wandb-metadata.json
2023-09-24 00:29:35,444 INFO    Thread-12 :805 [dir_watcher.py:_on_file_created():272] file/dir created: /mnt/d/PROJECTION/TianChi/STS-2D/wandb/run-20230924_002932-4tqudvuc/files/conda-environment.yaml
2023-09-24 00:29:35,446 INFO    Thread-12 :805 [dir_watcher.py:_on_file_created():272] file/dir created: /mnt/d/PROJECTION/TianChi/STS-2D/wandb/run-20230924_002932-4tqudvuc/files/wandb-summary.json
2023-09-24 00:29:35,578 DEBUG   SenderThread:805 [sender.py:send():369] send: telemetry
2023-09-24 00:29:35,929 ERROR   wandb-upload_0:805 [internal_api.py:upload_file():2192] upload_file exception https://storage.googleapis.com/wandb-production.appspot.com/zhuangy/STS-2D/4tqudvuc/wandb-metadata.json?Expires=1695572975&GoogleAccessId=gorilla-files-url-signer-man%40wandb-production.iam.gserviceaccount.com&Signature=e7sB5o1ZeZtEtUNiD2MEbDAsAlAehXamfPoBSSJtRiUL6NdozOY5kxqm2Yb3n1leStX%2B5Spi%2Fyz054A8HPGgwTNGQiOYVvOAka%2F%2BKdzYDBcycrN9pRlgxj6vDqrk0nFlnYMRnnabesxcYpHp4KyfHWdOyq05TgZMIKYu8PAJ%2FpNX59iIfeHAJt1N2mhY1Wj0Lb5xSWHeSh1VsU24JMu6GwiNr1c1bcqoKtHZC2WnVMNj%2FNume4CloKINPANhEJfKkDfSJe1jQmpQ7%2FqhRtB2nj4bJ9Yyx7Q8FSVjz5ddDTepRV8%2Foed7ao75Ii34gGq9OwzUQZXqmfuljGBBIGVBRw%3D%3D: ('Connection aborted.', ConnectionResetError(104, 'Connection reset by peer'))
2023-09-24 00:29:35,930 ERROR   wandb-upload_0:805 [internal_api.py:upload_file():2194] upload_file request headers: {'User-Agent': 'python-requests/2.29.0', 'Accept-Encoding': 'gzip, deflate, br', 'Accept': '*/*', 'Connection': 'keep-alive', 'Content-Length': '1354'}
2023-09-24 00:29:35,930 ERROR   wandb-upload_0:805 [internal_api.py:upload_file():2196] upload_file response body: 
2023-09-24 00:29:36,455 INFO    Thread-12 :805 [dir_watcher.py:_on_file_created():272] file/dir created: /mnt/d/PROJECTION/TianChi/STS-2D/wandb/run-20230924_002932-4tqudvuc/files/output.log
2023-09-24 00:29:37,444 ERROR   wandb-upload_0:805 [internal_api.py:upload_file():2192] upload_file exception https://storage.googleapis.com/wandb-production.appspot.com/zhuangy/STS-2D/4tqudvuc/wandb-metadata.json?Expires=1695572975&GoogleAccessId=gorilla-files-url-signer-man%40wandb-production.iam.gserviceaccount.com&Signature=e7sB5o1ZeZtEtUNiD2MEbDAsAlAehXamfPoBSSJtRiUL6NdozOY5kxqm2Yb3n1leStX%2B5Spi%2Fyz054A8HPGgwTNGQiOYVvOAka%2F%2BKdzYDBcycrN9pRlgxj6vDqrk0nFlnYMRnnabesxcYpHp4KyfHWdOyq05TgZMIKYu8PAJ%2FpNX59iIfeHAJt1N2mhY1Wj0Lb5xSWHeSh1VsU24JMu6GwiNr1c1bcqoKtHZC2WnVMNj%2FNume4CloKINPANhEJfKkDfSJe1jQmpQ7%2FqhRtB2nj4bJ9Yyx7Q8FSVjz5ddDTepRV8%2Foed7ao75Ii34gGq9OwzUQZXqmfuljGBBIGVBRw%3D%3D: ('Connection aborted.', ConnectionResetError(104, 'Connection reset by peer'))
2023-09-24 00:29:37,445 ERROR   wandb-upload_0:805 [internal_api.py:upload_file():2194] upload_file request headers: {'User-Agent': 'python-requests/2.29.0', 'Accept-Encoding': 'gzip, deflate, br', 'Accept': '*/*', 'Connection': 'keep-alive', 'Content-Length': '1354'}
2023-09-24 00:29:37,445 ERROR   wandb-upload_0:805 [internal_api.py:upload_file():2196] upload_file response body: 
2023-09-24 00:29:38,467 INFO    Thread-12 :805 [dir_watcher.py:_on_file_modified():289] file/dir modified: /mnt/d/PROJECTION/TianChi/STS-2D/wandb/run-20230924_002932-4tqudvuc/files/output.log
2023-09-24 00:29:38,593 DEBUG   HandlerThread:805 [handler.py:handle_request():144] handle_request: status_report
2023-09-24 00:29:40,513 ERROR   wandb-upload_0:805 [internal_api.py:upload_file():2192] upload_file exception https://storage.googleapis.com/wandb-production.appspot.com/zhuangy/STS-2D/4tqudvuc/wandb-metadata.json?Expires=1695572975&GoogleAccessId=gorilla-files-url-signer-man%40wandb-production.iam.gserviceaccount.com&Signature=e7sB5o1ZeZtEtUNiD2MEbDAsAlAehXamfPoBSSJtRiUL6NdozOY5kxqm2Yb3n1leStX%2B5Spi%2Fyz054A8HPGgwTNGQiOYVvOAka%2F%2BKdzYDBcycrN9pRlgxj6vDqrk0nFlnYMRnnabesxcYpHp4KyfHWdOyq05TgZMIKYu8PAJ%2FpNX59iIfeHAJt1N2mhY1Wj0Lb5xSWHeSh1VsU24JMu6GwiNr1c1bcqoKtHZC2WnVMNj%2FNume4CloKINPANhEJfKkDfSJe1jQmpQ7%2FqhRtB2nj4bJ9Yyx7Q8FSVjz5ddDTepRV8%2Foed7ao75Ii34gGq9OwzUQZXqmfuljGBBIGVBRw%3D%3D: ('Connection aborted.', ConnectionResetError(104, 'Connection reset by peer'))
2023-09-24 00:29:40,514 ERROR   wandb-upload_0:805 [internal_api.py:upload_file():2194] upload_file request headers: {'User-Agent': 'python-requests/2.29.0', 'Accept-Encoding': 'gzip, deflate, br', 'Accept': '*/*', 'Connection': 'keep-alive', 'Content-Length': '1354'}
2023-09-24 00:29:40,514 ERROR   wandb-upload_0:805 [internal_api.py:upload_file():2196] upload_file response body: 
2023-09-24 00:29:40,514 INFO    wandb-upload_0:805 [retry.py:__call__():172] Retry attempt failed:
Traceback (most recent call last):
  File "/home/zy/anaconda3/envs/kaggle_torch/lib/python3.9/site-packages/urllib3/connectionpool.py", line 703, in urlopen
    httplib_response = self._make_request(
  File "/home/zy/anaconda3/envs/kaggle_torch/lib/python3.9/site-packages/urllib3/connectionpool.py", line 386, in _make_request
    self._validate_conn(conn)
  File "/home/zy/anaconda3/envs/kaggle_torch/lib/python3.9/site-packages/urllib3/connectionpool.py", line 1042, in _validate_conn
    conn.connect()
  File "/home/zy/anaconda3/envs/kaggle_torch/lib/python3.9/site-packages/urllib3/connection.py", line 419, in connect
    self.sock = ssl_wrap_socket(
  File "/home/zy/anaconda3/envs/kaggle_torch/lib/python3.9/site-packages/urllib3/util/ssl_.py", line 449, in ssl_wrap_socket
    ssl_sock = _ssl_wrap_socket_impl(
  File "/home/zy/anaconda3/envs/kaggle_torch/lib/python3.9/site-packages/urllib3/util/ssl_.py", line 493, in _ssl_wrap_socket_impl
    return ssl_context.wrap_socket(sock, server_hostname=server_hostname)
  File "/home/zy/anaconda3/envs/kaggle_torch/lib/python3.9/ssl.py", line 501, in wrap_socket
    return self.sslsocket_class._create(
  File "/home/zy/anaconda3/envs/kaggle_torch/lib/python3.9/ssl.py", line 1041, in _create
    self.do_handshake()
  File "/home/zy/anaconda3/envs/kaggle_torch/lib/python3.9/ssl.py", line 1310, in do_handshake
    self._sslobj.do_handshake()
ConnectionResetError: [Errno 104] Connection reset by peer

During handling of the above exception, another exception occurred:

Traceback (most recent call last):
  File "/home/zy/anaconda3/envs/kaggle_torch/lib/python3.9/site-packages/requests/adapters.py", line 487, in send
    resp = conn.urlopen(
  File "/home/zy/anaconda3/envs/kaggle_torch/lib/python3.9/site-packages/urllib3/connectionpool.py", line 787, in urlopen
    retries = retries.increment(
  File "/home/zy/anaconda3/envs/kaggle_torch/lib/python3.9/site-packages/urllib3/util/retry.py", line 550, in increment
    raise six.reraise(type(error), error, _stacktrace)
  File "/home/zy/anaconda3/envs/kaggle_torch/lib/python3.9/site-packages/urllib3/packages/six.py", line 769, in reraise
    raise value.with_traceback(tb)
  File "/home/zy/anaconda3/envs/kaggle_torch/lib/python3.9/site-packages/urllib3/connectionpool.py", line 703, in urlopen
    httplib_response = self._make_request(
  File "/home/zy/anaconda3/envs/kaggle_torch/lib/python3.9/site-packages/urllib3/connectionpool.py", line 386, in _make_request
    self._validate_conn(conn)
  File "/home/zy/anaconda3/envs/kaggle_torch/lib/python3.9/site-packages/urllib3/connectionpool.py", line 1042, in _validate_conn
    conn.connect()
  File "/home/zy/anaconda3/envs/kaggle_torch/lib/python3.9/site-packages/urllib3/connection.py", line 419, in connect
    self.sock = ssl_wrap_socket(
  File "/home/zy/anaconda3/envs/kaggle_torch/lib/python3.9/site-packages/urllib3/util/ssl_.py", line 449, in ssl_wrap_socket
    ssl_sock = _ssl_wrap_socket_impl(
  File "/home/zy/anaconda3/envs/kaggle_torch/lib/python3.9/site-packages/urllib3/util/ssl_.py", line 493, in _ssl_wrap_socket_impl
    return ssl_context.wrap_socket(sock, server_hostname=server_hostname)
  File "/home/zy/anaconda3/envs/kaggle_torch/lib/python3.9/ssl.py", line 501, in wrap_socket
    return self.sslsocket_class._create(
  File "/home/zy/anaconda3/envs/kaggle_torch/lib/python3.9/ssl.py", line 1041, in _create
    self.do_handshake()
  File "/home/zy/anaconda3/envs/kaggle_torch/lib/python3.9/ssl.py", line 1310, in do_handshake
    self._sslobj.do_handshake()
urllib3.exceptions.ProtocolError: ('Connection aborted.', ConnectionResetError(104, 'Connection reset by peer'))

During handling of the above exception, another exception occurred:

Traceback (most recent call last):
  File "/home/zy/anaconda3/envs/kaggle_torch/lib/python3.9/site-packages/wandb/sdk/internal/internal_api.py", line 2187, in upload_file
    response = self._upload_file_session.put(
  File "/home/zy/anaconda3/envs/kaggle_torch/lib/python3.9/site-packages/requests/sessions.py", line 647, in put
    return self.request("PUT", url, data=data, **kwargs)
  File "/home/zy/anaconda3/envs/kaggle_torch/lib/python3.9/site-packages/requests/sessions.py", line 587, in request
    resp = self.send(prep, **send_kwargs)
  File "/home/zy/anaconda3/envs/kaggle_torch/lib/python3.9/site-packages/requests/sessions.py", line 701, in send
    r = adapter.send(request, **kwargs)
  File "/home/zy/anaconda3/envs/kaggle_torch/lib/python3.9/site-packages/requests/adapters.py", line 502, in send
    raise ConnectionError(err, request=request)
requests.exceptions.ConnectionError: ('Connection aborted.', ConnectionResetError(104, 'Connection reset by peer'))

During handling of the above exception, another exception occurred:

Traceback (most recent call last):
  File "/home/zy/anaconda3/envs/kaggle_torch/lib/python3.9/site-packages/wandb/sdk/lib/retry.py", line 131, in __call__
    result = self._call_fn(*args, **kwargs)
  File "/home/zy/anaconda3/envs/kaggle_torch/lib/python3.9/site-packages/wandb/sdk/internal/internal_api.py", line 2216, in upload_file
    raise _e.with_traceback(sys.exc_info()[2])
  File "/home/zy/anaconda3/envs/kaggle_torch/lib/python3.9/site-packages/wandb/sdk/internal/internal_api.py", line 2187, in upload_file
    response = self._upload_file_session.put(
  File "/home/zy/anaconda3/envs/kaggle_torch/lib/python3.9/site-packages/requests/sessions.py", line 647, in put
    return self.request("PUT", url, data=data, **kwargs)
  File "/home/zy/anaconda3/envs/kaggle_torch/lib/python3.9/site-packages/requests/sessions.py", line 587, in request
    resp = self.send(prep, **send_kwargs)
  File "/home/zy/anaconda3/envs/kaggle_torch/lib/python3.9/site-packages/requests/sessions.py", line 701, in send
    r = adapter.send(request, **kwargs)
  File "/home/zy/anaconda3/envs/kaggle_torch/lib/python3.9/site-packages/requests/adapters.py", line 502, in send
    raise ConnectionError(err, request=request)
wandb.sdk.lib.retry.TransientError: None
2023-09-24 00:29:43,595 DEBUG   HandlerThread:805 [handler.py:handle_request():144] handle_request: status_report
2023-09-24 00:29:44,957 ERROR   wandb-upload_0:805 [internal_api.py:upload_file():2192] upload_file exception https://storage.googleapis.com/wandb-production.appspot.com/zhuangy/STS-2D/4tqudvuc/wandb-metadata.json?Expires=1695572975&GoogleAccessId=gorilla-files-url-signer-man%40wandb-production.iam.gserviceaccount.com&Signature=e7sB5o1ZeZtEtUNiD2MEbDAsAlAehXamfPoBSSJtRiUL6NdozOY5kxqm2Yb3n1leStX%2B5Spi%2Fyz054A8HPGgwTNGQiOYVvOAka%2F%2BKdzYDBcycrN9pRlgxj6vDqrk0nFlnYMRnnabesxcYpHp4KyfHWdOyq05TgZMIKYu8PAJ%2FpNX59iIfeHAJt1N2mhY1Wj0Lb5xSWHeSh1VsU24JMu6GwiNr1c1bcqoKtHZC2WnVMNj%2FNume4CloKINPANhEJfKkDfSJe1jQmpQ7%2FqhRtB2nj4bJ9Yyx7Q8FSVjz5ddDTepRV8%2Foed7ao75Ii34gGq9OwzUQZXqmfuljGBBIGVBRw%3D%3D: ('Connection aborted.', ConnectionResetError(104, 'Connection reset by peer'))
2023-09-24 00:29:44,958 ERROR   wandb-upload_0:805 [internal_api.py:upload_file():2194] upload_file request headers: {'User-Agent': 'python-requests/2.29.0', 'Accept-Encoding': 'gzip, deflate, br', 'Accept': '*/*', 'Connection': 'keep-alive', 'Content-Length': '1354'}
2023-09-24 00:29:44,958 ERROR   wandb-upload_0:805 [internal_api.py:upload_file():2196] upload_file response body: 
2023-09-24 00:29:48,596 DEBUG   HandlerThread:805 [handler.py:handle_request():144] handle_request: status_report
2023-09-24 00:29:53,597 DEBUG   HandlerThread:805 [handler.py:handle_request():144] handle_request: status_report
2023-09-24 00:29:55,231 ERROR   wandb-upload_0:805 [internal_api.py:upload_file():2192] upload_file exception https://storage.googleapis.com/wandb-production.appspot.com/zhuangy/STS-2D/4tqudvuc/wandb-metadata.json?Expires=1695572975&GoogleAccessId=gorilla-files-url-signer-man%40wandb-production.iam.gserviceaccount.com&Signature=e7sB5o1ZeZtEtUNiD2MEbDAsAlAehXamfPoBSSJtRiUL6NdozOY5kxqm2Yb3n1leStX%2B5Spi%2Fyz054A8HPGgwTNGQiOYVvOAka%2F%2BKdzYDBcycrN9pRlgxj6vDqrk0nFlnYMRnnabesxcYpHp4KyfHWdOyq05TgZMIKYu8PAJ%2FpNX59iIfeHAJt1N2mhY1Wj0Lb5xSWHeSh1VsU24JMu6GwiNr1c1bcqoKtHZC2WnVMNj%2FNume4CloKINPANhEJfKkDfSJe1jQmpQ7%2FqhRtB2nj4bJ9Yyx7Q8FSVjz5ddDTepRV8%2Foed7ao75Ii34gGq9OwzUQZXqmfuljGBBIGVBRw%3D%3D: ('Connection aborted.', ConnectionResetError(104, 'Connection reset by peer'))
2023-09-24 00:29:55,231 ERROR   wandb-upload_0:805 [internal_api.py:upload_file():2194] upload_file request headers: {'User-Agent': 'python-requests/2.29.0', 'Accept-Encoding': 'gzip, deflate, br', 'Accept': '*/*', 'Connection': 'keep-alive', 'Content-Length': '1354'}
2023-09-24 00:29:55,231 ERROR   wandb-upload_0:805 [internal_api.py:upload_file():2196] upload_file response body: 
2023-09-24 00:29:55,549 DEBUG   HandlerThread:805 [handler.py:handle_request():144] handle_request: stop_status
2023-09-24 00:29:55,554 DEBUG   SenderThread:805 [sender.py:send_request():396] send_request: stop_status
2023-09-24 00:29:58,942 DEBUG   HandlerThread:805 [handler.py:handle_request():144] handle_request: status_report
2023-09-24 00:30:02,204 INFO    cpu       :805 [interfaces.py:monitor():140] Process cpu has exited.
2023-09-24 00:30:02,205 DEBUG   SystemMonitor:805 [system_monitor.py:_start():159] Starting system metrics aggregation loop
2023-09-24 00:30:02,206 DEBUG   SystemMonitor:805 [system_monitor.py:_start():166] Finished system metrics aggregation loop
2023-09-24 00:30:02,206 DEBUG   SystemMonitor:805 [system_monitor.py:_start():170] Publishing last batch of metrics
2023-09-24 00:30:02,210 DEBUG   SenderThread:805 [sender.py:send():369] send: stats
2023-09-24 00:30:04,214 DEBUG   HandlerThread:805 [handler.py:handle_request():144] handle_request: status_report
2023-09-24 00:30:05,256 INFO    Thread-12 :805 [dir_watcher.py:_on_file_modified():289] file/dir modified: /mnt/d/PROJECTION/TianChi/STS-2D/wandb/run-20230924_002932-4tqudvuc/files/config.yaml
2023-09-24 00:30:05,889 WARNING StreamThr :805 [internal.py:is_dead():414] Internal process exiting, parent pid 785 disappeared
2023-09-24 00:30:05,889 ERROR   StreamThr :805 [internal.py:wandb_internal():152] Internal process shutdown.
2023-09-24 00:30:06,215 INFO    HandlerThread:805 [handler.py:finish():854] shutting down handler
2023-09-24 00:30:06,215 INFO    WriterThread:805 [datastore.py:close():298] close: /mnt/d/PROJECTION/TianChi/STS-2D/wandb/run-20230924_002932-4tqudvuc/run-4tqudvuc.wandb
2023-09-24 00:30:06,215 INFO    HandlerThread:805 [system_monitor.py:finish():190] Stopping system monitor
2023-09-24 00:30:06,216 INFO    HandlerThread:805 [interfaces.py:finish():202] Joined cpu monitor
2023-09-24 00:30:06,216 INFO    HandlerThread:805 [interfaces.py:finish():202] Joined disk monitor
2023-09-24 00:30:06,217 INFO    HandlerThread:805 [interfaces.py:finish():202] Joined memory monitor
2023-09-24 00:30:06,217 INFO    HandlerThread:805 [interfaces.py:finish():202] Joined network monitor
2023-09-24 00:30:06,602 INFO    SenderThread:805 [sender.py:finish():1526] shutting down sender
2023-09-24 00:30:08,214 INFO    SenderThread:805 [dir_watcher.py:finish():359] shutting down directory watcher
2023-09-24 00:30:08,263 INFO    SenderThread:805 [dir_watcher.py:_on_file_modified():289] file/dir modified: /mnt/d/PROJECTION/TianChi/STS-2D/wandb/run-20230924_002932-4tqudvuc/files/output.log
2023-09-24 00:30:08,269 INFO    SenderThread:805 [dir_watcher.py:finish():389] scan: /mnt/d/PROJECTION/TianChi/STS-2D/wandb/run-20230924_002932-4tqudvuc/files
2023-09-24 00:30:08,271 INFO    SenderThread:805 [dir_watcher.py:finish():403] scan save: /mnt/d/PROJECTION/TianChi/STS-2D/wandb/run-20230924_002932-4tqudvuc/files/conda-environment.yaml conda-environment.yaml
2023-09-24 00:30:08,274 INFO    SenderThread:805 [dir_watcher.py:finish():403] scan save: /mnt/d/PROJECTION/TianChi/STS-2D/wandb/run-20230924_002932-4tqudvuc/files/config.yaml config.yaml
2023-09-24 00:30:08,277 INFO    SenderThread:805 [dir_watcher.py:finish():403] scan save: /mnt/d/PROJECTION/TianChi/STS-2D/wandb/run-20230924_002932-4tqudvuc/files/output.log output.log
2023-09-24 00:30:08,281 INFO    SenderThread:805 [dir_watcher.py:finish():403] scan save: /mnt/d/PROJECTION/TianChi/STS-2D/wandb/run-20230924_002932-4tqudvuc/files/requirements.txt requirements.txt
2023-09-24 00:30:08,285 INFO    SenderThread:805 [dir_watcher.py:finish():403] scan save: /mnt/d/PROJECTION/TianChi/STS-2D/wandb/run-20230924_002932-4tqudvuc/files/wandb-metadata.json wandb-metadata.json
2023-09-24 00:30:08,285 INFO    SenderThread:805 [dir_watcher.py:finish():403] scan save: /mnt/d/PROJECTION/TianChi/STS-2D/wandb/run-20230924_002932-4tqudvuc/files/wandb-summary.json wandb-summary.json
2023-09-24 00:30:08,289 INFO    SenderThread:805 [file_pusher.py:finish():159] shutting down file pusher
2023-09-24 00:30:08,289 INFO    SenderThread:805 [file_pusher.py:join():164] waiting for file pusher
