using AttentionUnet for training.
train:
  0%|          | 0/522 [00:03<?, ?it/s]
Traceback (most recent call last):
  File "/mnt/d/PROJECTION/TianChi/STS-2D/train.py", line 193, in <module>
    train_loss = train_step(train_loader, model, criterion, optimizer, CFG.device, epoch)
  File "/mnt/d/PROJECTION/TianChi/STS-2D/train.py", line 68, in train_step
    outputs = model(image.to(device))
  File "/home/zy/anaconda3/envs/kaggle_torch/lib/python3.9/site-packages/torch/nn/modules/module.py", line 1501, in _call_impl
    return forward_call(*args, **kwargs)
  File "/mnt/d/PROJECTION/TianChi/STS-2D/models.py", line 81, in forward
    x = self.model(x)
  File "/home/zy/anaconda3/envs/kaggle_torch/lib/python3.9/site-packages/torch/nn/modules/module.py", line 1501, in _call_impl
    return forward_call(*args, **kwargs)
  File "/home/zy/anaconda3/envs/kaggle_torch/lib/python3.9/site-packages/monai/networks/nets/attentionunet.py", line 275, in forward
    x_m: torch.Tensor = self.model(x)
  File "/home/zy/anaconda3/envs/kaggle_torch/lib/python3.9/site-packages/torch/nn/modules/module.py", line 1501, in _call_impl
    return forward_call(*args, **kwargs)
  File "/home/zy/anaconda3/envs/kaggle_torch/lib/python3.9/site-packages/torch/nn/modules/container.py", line 217, in forward
    input = module(input)
  File "/home/zy/anaconda3/envs/kaggle_torch/lib/python3.9/site-packages/torch/nn/modules/module.py", line 1501, in _call_impl
    return forward_call(*args, **kwargs)
  File "/home/zy/anaconda3/envs/kaggle_torch/lib/python3.9/site-packages/monai/networks/nets/attentionunet.py", line 175, in forward
    att_m: torch.Tensor = self.merge(torch.cat((att, fromlower), dim=1))
RuntimeError: CUDA error: unknown error
CUDA kernel errors might be asynchronously reported at some other API call, so the stacktrace below might be incorrect.
For debugging consider passing CUDA_LAUNCH_BLOCKING=1.
Compile with `TORCH_USE_CUDA_DSA` to enable device-side assertions.