2023-09-24 00:31:52,382 INFO    StreamThr :917 [internal.py:wandb_internal():86] W&B internal server running at pid: 917, started at: 2023-09-24 00:31:52.381685
2023-09-24 00:31:52,384 DEBUG   HandlerThread:917 [handler.py:handle_request():144] handle_request: status
2023-09-24 00:31:52,386 INFO    WriterThread:917 [datastore.py:open_for_write():85] open: /mnt/d/PROJECTION/TianChi/STS-2D/wandb/run-20230924_003152-faesnysg/run-faesnysg.wandb
2023-09-24 00:31:52,394 DEBUG   SenderThread:917 [sender.py:send():369] send: header
2023-09-24 00:31:52,394 DEBUG   SenderThread:917 [sender.py:send():369] send: run
2023-09-24 00:31:53,944 DEBUG   HandlerThread:917 [handler.py:handle_request():144] handle_request: check_version
2023-09-24 00:31:53,945 INFO    SenderThread:917 [dir_watcher.py:__init__():211] watching files in: /mnt/d/PROJECTION/TianChi/STS-2D/wandb/run-20230924_003152-faesnysg/files
2023-09-24 00:31:53,945 INFO    SenderThread:917 [sender.py:_start_run_threads():1100] run started: faesnysg with start time 1695486712.382384
2023-09-24 00:31:53,945 DEBUG   SenderThread:917 [sender.py:send_request():396] send_request: summary_record
2023-09-24 00:31:53,948 INFO    SenderThread:917 [sender.py:_save_file():1354] saving file wandb-summary.json with policy end
2023-09-24 00:31:53,950 DEBUG   SenderThread:917 [sender.py:send_request():396] send_request: check_version
2023-09-24 00:31:54,801 DEBUG   HandlerThread:917 [handler.py:handle_request():144] handle_request: run_start
2023-09-24 00:31:54,813 ERROR   HandlerThread:917 [gpu.py:is_available():381] Error initializing NVML: The operating system has blocked the request.
2023-09-24 00:31:54,813 DEBUG   HandlerThread:917 [system_info.py:__init__():31] System info init
2023-09-24 00:31:54,813 DEBUG   HandlerThread:917 [system_info.py:__init__():46] System info init done
2023-09-24 00:31:54,814 INFO    HandlerThread:917 [system_monitor.py:start():181] Starting system monitor
2023-09-24 00:31:54,814 INFO    SystemMonitor:917 [system_monitor.py:_start():145] Starting system asset monitoring threads
2023-09-24 00:31:54,814 INFO    HandlerThread:917 [system_monitor.py:probe():201] Collecting system info
2023-09-24 00:31:54,815 INFO    SystemMonitor:917 [interfaces.py:start():190] Started cpu monitoring
2023-09-24 00:31:54,816 INFO    SystemMonitor:917 [interfaces.py:start():190] Started disk monitoring
2023-09-24 00:31:54,816 INFO    SystemMonitor:917 [interfaces.py:start():190] Started memory monitoring
2023-09-24 00:31:54,817 INFO    SystemMonitor:917 [interfaces.py:start():190] Started network monitoring
2023-09-24 00:31:54,819 DEBUG   HandlerThread:917 [system_info.py:probe():195] Probing system
2023-09-24 00:31:54,855 DEBUG   HandlerThread:917 [gitlib.py:_init_repo():53] git repository is invalid
2023-09-24 00:31:54,855 DEBUG   HandlerThread:917 [system_info.py:probe():240] Probing system done
2023-09-24 00:31:54,855 DEBUG   HandlerThread:917 [system_monitor.py:probe():210] {'os': 'Linux-5.10.16.3-microsoft-standard-WSL2-x86_64-with-glibc2.35', 'python': '3.9.16', 'heartbeatAt': '2023-09-23T16:31:54.819594', 'startedAt': '2023-09-23T16:31:52.348038', 'docker': None, 'cuda': None, 'args': ('wandb', 'login'), 'state': 'running', 'program': '/mnt/d/PROJECTION/TianChi/STS-2D/train.py', 'codePath': 'train.py', 'host': 'DESKTOP-LT0ASMB', 'username': 'zy', 'executable': '/home/zy/anaconda3/envs/kaggle_torch/bin/python3', 'cpu_count': 3, 'cpu_count_logical': 5, 'cpu_freq': {'current': 3192.008, 'min': 0.0, 'max': 0.0}, 'cpu_freq_per_core': [{'current': 3192.008, 'min': 0.0, 'max': 0.0}, {'current': 3192.008, 'min': 0.0, 'max': 0.0}, {'current': 3192.008, 'min': 0.0, 'max': 0.0}, {'current': 3192.008, 'min': 0.0, 'max': 0.0}, {'current': 3192.008, 'min': 0.0, 'max': 0.0}], 'disk': {'total': 250.98248672485352, 'used': 63.60941696166992}, 'memory': {'total': 24.93661880493164}}
2023-09-24 00:31:54,855 INFO    HandlerThread:917 [system_monitor.py:probe():211] Finished collecting system info
2023-09-24 00:31:54,856 INFO    HandlerThread:917 [system_monitor.py:probe():214] Publishing system info
2023-09-24 00:31:54,856 DEBUG   HandlerThread:917 [system_info.py:_save_pip():51] Saving list of pip packages installed into the current environment
2023-09-24 00:31:54,858 DEBUG   HandlerThread:917 [system_info.py:_save_pip():67] Saving pip packages done
2023-09-24 00:31:54,859 DEBUG   HandlerThread:917 [system_info.py:_save_conda():74] Saving list of conda packages installed into the current environment
2023-09-24 00:31:54,895 ERROR   HandlerThread:917 [system_info.py:_save_conda():85] Error saving conda packages: [Errno 2] No such file or directory: 'conda'
Traceback (most recent call last):
  File "/home/zy/anaconda3/envs/kaggle_torch/lib/python3.9/site-packages/wandb/sdk/internal/system/system_info.py", line 81, in _save_conda
    subprocess.call(
  File "/home/zy/anaconda3/envs/kaggle_torch/lib/python3.9/subprocess.py", line 349, in call
    with Popen(*popenargs, **kwargs) as p:
  File "/home/zy/anaconda3/envs/kaggle_torch/lib/python3.9/subprocess.py", line 951, in __init__
    self._execute_child(args, executable, preexec_fn, close_fds,
  File "/home/zy/anaconda3/envs/kaggle_torch/lib/python3.9/subprocess.py", line 1821, in _execute_child
    raise child_exception_type(errno_num, err_msg, err_filename)
FileNotFoundError: [Errno 2] No such file or directory: 'conda'
2023-09-24 00:31:54,897 DEBUG   HandlerThread:917 [system_info.py:_save_conda():86] Saving conda packages done
2023-09-24 00:31:54,899 INFO    HandlerThread:917 [system_monitor.py:probe():216] Finished publishing system info
2023-09-24 00:31:54,906 DEBUG   SenderThread:917 [sender.py:send():369] send: files
2023-09-24 00:31:54,907 INFO    SenderThread:917 [sender.py:_save_file():1354] saving file wandb-metadata.json with policy now
2023-09-24 00:31:54,913 DEBUG   HandlerThread:917 [handler.py:handle_request():144] handle_request: stop_status
2023-09-24 00:31:54,913 DEBUG   SenderThread:917 [sender.py:send_request():396] send_request: stop_status
2023-09-24 00:31:54,953 INFO    Thread-12 :917 [dir_watcher.py:_on_file_created():272] file/dir created: /mnt/d/PROJECTION/TianChi/STS-2D/wandb/run-20230924_003152-faesnysg/files/wandb-metadata.json
2023-09-24 00:31:54,954 INFO    Thread-12 :917 [dir_watcher.py:_on_file_created():272] file/dir created: /mnt/d/PROJECTION/TianChi/STS-2D/wandb/run-20230924_003152-faesnysg/files/wandb-summary.json
2023-09-24 00:31:54,955 INFO    Thread-12 :917 [dir_watcher.py:_on_file_created():272] file/dir created: /mnt/d/PROJECTION/TianChi/STS-2D/wandb/run-20230924_003152-faesnysg/files/requirements.txt
2023-09-24 00:31:54,956 INFO    Thread-12 :917 [dir_watcher.py:_on_file_created():272] file/dir created: /mnt/d/PROJECTION/TianChi/STS-2D/wandb/run-20230924_003152-faesnysg/files/conda-environment.yaml
2023-09-24 00:31:55,250 DEBUG   SenderThread:917 [sender.py:send():369] send: telemetry
2023-09-24 00:31:55,958 INFO    Thread-12 :917 [dir_watcher.py:_on_file_created():272] file/dir created: /mnt/d/PROJECTION/TianChi/STS-2D/wandb/run-20230924_003152-faesnysg/files/output.log
2023-09-24 00:31:56,615 ERROR   wandb-upload_0:917 [internal_api.py:upload_file():2192] upload_file exception https://storage.googleapis.com/wandb-production.appspot.com/zhuangy/STS-2D/faesnysg/wandb-metadata.json?Expires=1695573115&GoogleAccessId=gorilla-files-url-signer-man%40wandb-production.iam.gserviceaccount.com&Signature=TOuWzo8zk3kLnAMnWVNi60iKJmnGaj0Sb5khlfX7FL7nIIfZUNMk49npLFChFe1P2eH3ww9CBNN98C9I8DCS9RNAQdp6kViCsfVETiexiZTGK8cQYX%2Fn1IVmaJtVRJ5DXFjuBpfAUQ5XD6tijc0aLNpLu8dZMF%2B2g5FtzT7W1NhT76WaZMf0RXrfhn5lBK12j930its2k3xmhfix6p%2FragD7SalcMA9OEeAqOew3HgWU4bzZpyMh4owlmZKnFPfmL3TjxE5VLOcy49NjD8giCtv76mEeKEAQlT5rngUMXh1%2F3A8uhJANVLjpG%2FLrI3F4ifoNjtme%2FORC2WVmF%2Fb22w%3D%3D: ('Connection aborted.', ConnectionResetError(104, 'Connection reset by peer'))
2023-09-24 00:31:56,615 ERROR   wandb-upload_0:917 [internal_api.py:upload_file():2194] upload_file request headers: {'User-Agent': 'python-requests/2.29.0', 'Accept-Encoding': 'gzip, deflate, br', 'Accept': '*/*', 'Connection': 'keep-alive', 'Content-Length': '1354'}
2023-09-24 00:31:56,616 ERROR   wandb-upload_0:917 [internal_api.py:upload_file():2196] upload_file response body: 
2023-09-24 00:31:57,967 INFO    Thread-12 :917 [dir_watcher.py:_on_file_modified():289] file/dir modified: /mnt/d/PROJECTION/TianChi/STS-2D/wandb/run-20230924_003152-faesnysg/files/output.log
2023-09-24 00:31:58,262 DEBUG   HandlerThread:917 [handler.py:handle_request():144] handle_request: status_report
2023-09-24 00:31:58,388 ERROR   wandb-upload_0:917 [internal_api.py:upload_file():2192] upload_file exception https://storage.googleapis.com/wandb-production.appspot.com/zhuangy/STS-2D/faesnysg/wandb-metadata.json?Expires=1695573115&GoogleAccessId=gorilla-files-url-signer-man%40wandb-production.iam.gserviceaccount.com&Signature=TOuWzo8zk3kLnAMnWVNi60iKJmnGaj0Sb5khlfX7FL7nIIfZUNMk49npLFChFe1P2eH3ww9CBNN98C9I8DCS9RNAQdp6kViCsfVETiexiZTGK8cQYX%2Fn1IVmaJtVRJ5DXFjuBpfAUQ5XD6tijc0aLNpLu8dZMF%2B2g5FtzT7W1NhT76WaZMf0RXrfhn5lBK12j930its2k3xmhfix6p%2FragD7SalcMA9OEeAqOew3HgWU4bzZpyMh4owlmZKnFPfmL3TjxE5VLOcy49NjD8giCtv76mEeKEAQlT5rngUMXh1%2F3A8uhJANVLjpG%2FLrI3F4ifoNjtme%2FORC2WVmF%2Fb22w%3D%3D: ('Connection aborted.', ConnectionResetError(104, 'Connection reset by peer'))
2023-09-24 00:31:58,388 ERROR   wandb-upload_0:917 [internal_api.py:upload_file():2194] upload_file request headers: {'User-Agent': 'python-requests/2.29.0', 'Accept-Encoding': 'gzip, deflate, br', 'Accept': '*/*', 'Connection': 'keep-alive', 'Content-Length': '1354'}
2023-09-24 00:31:58,389 ERROR   wandb-upload_0:917 [internal_api.py:upload_file():2196] upload_file response body: 
2023-09-24 00:32:01,102 ERROR   wandb-upload_0:917 [internal_api.py:upload_file():2192] upload_file exception https://storage.googleapis.com/wandb-production.appspot.com/zhuangy/STS-2D/faesnysg/wandb-metadata.json?Expires=1695573115&GoogleAccessId=gorilla-files-url-signer-man%40wandb-production.iam.gserviceaccount.com&Signature=TOuWzo8zk3kLnAMnWVNi60iKJmnGaj0Sb5khlfX7FL7nIIfZUNMk49npLFChFe1P2eH3ww9CBNN98C9I8DCS9RNAQdp6kViCsfVETiexiZTGK8cQYX%2Fn1IVmaJtVRJ5DXFjuBpfAUQ5XD6tijc0aLNpLu8dZMF%2B2g5FtzT7W1NhT76WaZMf0RXrfhn5lBK12j930its2k3xmhfix6p%2FragD7SalcMA9OEeAqOew3HgWU4bzZpyMh4owlmZKnFPfmL3TjxE5VLOcy49NjD8giCtv76mEeKEAQlT5rngUMXh1%2F3A8uhJANVLjpG%2FLrI3F4ifoNjtme%2FORC2WVmF%2Fb22w%3D%3D: ('Connection aborted.', ConnectionResetError(104, 'Connection reset by peer'))
2023-09-24 00:32:01,102 ERROR   wandb-upload_0:917 [internal_api.py:upload_file():2194] upload_file request headers: {'User-Agent': 'python-requests/2.29.0', 'Accept-Encoding': 'gzip, deflate, br', 'Accept': '*/*', 'Connection': 'keep-alive', 'Content-Length': '1354'}
2023-09-24 00:32:01,103 ERROR   wandb-upload_0:917 [internal_api.py:upload_file():2196] upload_file response body: 
2023-09-24 00:32:01,103 INFO    wandb-upload_0:917 [retry.py:__call__():172] Retry attempt failed:
Traceback (most recent call last):
  File "/home/zy/anaconda3/envs/kaggle_torch/lib/python3.9/site-packages/urllib3/connectionpool.py", line 703, in urlopen
    httplib_response = self._make_request(
  File "/home/zy/anaconda3/envs/kaggle_torch/lib/python3.9/site-packages/urllib3/connectionpool.py", line 386, in _make_request
    self._validate_conn(conn)
  File "/home/zy/anaconda3/envs/kaggle_torch/lib/python3.9/site-packages/urllib3/connectionpool.py", line 1042, in _validate_conn
    conn.connect()
  File "/home/zy/anaconda3/envs/kaggle_torch/lib/python3.9/site-packages/urllib3/connection.py", line 419, in connect
    self.sock = ssl_wrap_socket(
  File "/home/zy/anaconda3/envs/kaggle_torch/lib/python3.9/site-packages/urllib3/util/ssl_.py", line 449, in ssl_wrap_socket
    ssl_sock = _ssl_wrap_socket_impl(
  File "/home/zy/anaconda3/envs/kaggle_torch/lib/python3.9/site-packages/urllib3/util/ssl_.py", line 493, in _ssl_wrap_socket_impl
    return ssl_context.wrap_socket(sock, server_hostname=server_hostname)
  File "/home/zy/anaconda3/envs/kaggle_torch/lib/python3.9/ssl.py", line 501, in wrap_socket
    return self.sslsocket_class._create(
  File "/home/zy/anaconda3/envs/kaggle_torch/lib/python3.9/ssl.py", line 1041, in _create
    self.do_handshake()
  File "/home/zy/anaconda3/envs/kaggle_torch/lib/python3.9/ssl.py", line 1310, in do_handshake
    self._sslobj.do_handshake()
ConnectionResetError: [Errno 104] Connection reset by peer

During handling of the above exception, another exception occurred:

Traceback (most recent call last):
  File "/home/zy/anaconda3/envs/kaggle_torch/lib/python3.9/site-packages/requests/adapters.py", line 487, in send
    resp = conn.urlopen(
  File "/home/zy/anaconda3/envs/kaggle_torch/lib/python3.9/site-packages/urllib3/connectionpool.py", line 787, in urlopen
    retries = retries.increment(
  File "/home/zy/anaconda3/envs/kaggle_torch/lib/python3.9/site-packages/urllib3/util/retry.py", line 550, in increment
    raise six.reraise(type(error), error, _stacktrace)
  File "/home/zy/anaconda3/envs/kaggle_torch/lib/python3.9/site-packages/urllib3/packages/six.py", line 769, in reraise
    raise value.with_traceback(tb)
  File "/home/zy/anaconda3/envs/kaggle_torch/lib/python3.9/site-packages/urllib3/connectionpool.py", line 703, in urlopen
    httplib_response = self._make_request(
  File "/home/zy/anaconda3/envs/kaggle_torch/lib/python3.9/site-packages/urllib3/connectionpool.py", line 386, in _make_request
    self._validate_conn(conn)
  File "/home/zy/anaconda3/envs/kaggle_torch/lib/python3.9/site-packages/urllib3/connectionpool.py", line 1042, in _validate_conn
    conn.connect()
  File "/home/zy/anaconda3/envs/kaggle_torch/lib/python3.9/site-packages/urllib3/connection.py", line 419, in connect
    self.sock = ssl_wrap_socket(
  File "/home/zy/anaconda3/envs/kaggle_torch/lib/python3.9/site-packages/urllib3/util/ssl_.py", line 449, in ssl_wrap_socket
    ssl_sock = _ssl_wrap_socket_impl(
  File "/home/zy/anaconda3/envs/kaggle_torch/lib/python3.9/site-packages/urllib3/util/ssl_.py", line 493, in _ssl_wrap_socket_impl
    return ssl_context.wrap_socket(sock, server_hostname=server_hostname)
  File "/home/zy/anaconda3/envs/kaggle_torch/lib/python3.9/ssl.py", line 501, in wrap_socket
    return self.sslsocket_class._create(
  File "/home/zy/anaconda3/envs/kaggle_torch/lib/python3.9/ssl.py", line 1041, in _create
    self.do_handshake()
  File "/home/zy/anaconda3/envs/kaggle_torch/lib/python3.9/ssl.py", line 1310, in do_handshake
    self._sslobj.do_handshake()
urllib3.exceptions.ProtocolError: ('Connection aborted.', ConnectionResetError(104, 'Connection reset by peer'))

During handling of the above exception, another exception occurred:

Traceback (most recent call last):
  File "/home/zy/anaconda3/envs/kaggle_torch/lib/python3.9/site-packages/wandb/sdk/internal/internal_api.py", line 2187, in upload_file
    response = self._upload_file_session.put(
  File "/home/zy/anaconda3/envs/kaggle_torch/lib/python3.9/site-packages/requests/sessions.py", line 647, in put
    return self.request("PUT", url, data=data, **kwargs)
  File "/home/zy/anaconda3/envs/kaggle_torch/lib/python3.9/site-packages/requests/sessions.py", line 587, in request
    resp = self.send(prep, **send_kwargs)
  File "/home/zy/anaconda3/envs/kaggle_torch/lib/python3.9/site-packages/requests/sessions.py", line 701, in send
    r = adapter.send(request, **kwargs)
  File "/home/zy/anaconda3/envs/kaggle_torch/lib/python3.9/site-packages/requests/adapters.py", line 502, in send
    raise ConnectionError(err, request=request)
requests.exceptions.ConnectionError: ('Connection aborted.', ConnectionResetError(104, 'Connection reset by peer'))

During handling of the above exception, another exception occurred:

Traceback (most recent call last):
  File "/home/zy/anaconda3/envs/kaggle_torch/lib/python3.9/site-packages/wandb/sdk/lib/retry.py", line 131, in __call__
    result = self._call_fn(*args, **kwargs)
  File "/home/zy/anaconda3/envs/kaggle_torch/lib/python3.9/site-packages/wandb/sdk/internal/internal_api.py", line 2216, in upload_file
    raise _e.with_traceback(sys.exc_info()[2])
  File "/home/zy/anaconda3/envs/kaggle_torch/lib/python3.9/site-packages/wandb/sdk/internal/internal_api.py", line 2187, in upload_file
    response = self._upload_file_session.put(
  File "/home/zy/anaconda3/envs/kaggle_torch/lib/python3.9/site-packages/requests/sessions.py", line 647, in put
    return self.request("PUT", url, data=data, **kwargs)
  File "/home/zy/anaconda3/envs/kaggle_torch/lib/python3.9/site-packages/requests/sessions.py", line 587, in request
    resp = self.send(prep, **send_kwargs)
  File "/home/zy/anaconda3/envs/kaggle_torch/lib/python3.9/site-packages/requests/sessions.py", line 701, in send
    r = adapter.send(request, **kwargs)
  File "/home/zy/anaconda3/envs/kaggle_torch/lib/python3.9/site-packages/requests/adapters.py", line 502, in send
    raise ConnectionError(err, request=request)
wandb.sdk.lib.retry.TransientError: None
2023-09-24 00:32:03,263 DEBUG   HandlerThread:917 [handler.py:handle_request():144] handle_request: status_report
2023-09-24 00:32:05,823 ERROR   wandb-upload_0:917 [internal_api.py:upload_file():2192] upload_file exception https://storage.googleapis.com/wandb-production.appspot.com/zhuangy/STS-2D/faesnysg/wandb-metadata.json?Expires=1695573115&GoogleAccessId=gorilla-files-url-signer-man%40wandb-production.iam.gserviceaccount.com&Signature=TOuWzo8zk3kLnAMnWVNi60iKJmnGaj0Sb5khlfX7FL7nIIfZUNMk49npLFChFe1P2eH3ww9CBNN98C9I8DCS9RNAQdp6kViCsfVETiexiZTGK8cQYX%2Fn1IVmaJtVRJ5DXFjuBpfAUQ5XD6tijc0aLNpLu8dZMF%2B2g5FtzT7W1NhT76WaZMf0RXrfhn5lBK12j930its2k3xmhfix6p%2FragD7SalcMA9OEeAqOew3HgWU4bzZpyMh4owlmZKnFPfmL3TjxE5VLOcy49NjD8giCtv76mEeKEAQlT5rngUMXh1%2F3A8uhJANVLjpG%2FLrI3F4ifoNjtme%2FORC2WVmF%2Fb22w%3D%3D: ('Connection aborted.', ConnectionResetError(104, 'Connection reset by peer'))
2023-09-24 00:32:05,823 ERROR   wandb-upload_0:917 [internal_api.py:upload_file():2194] upload_file request headers: {'User-Agent': 'python-requests/2.29.0', 'Accept-Encoding': 'gzip, deflate, br', 'Accept': '*/*', 'Connection': 'keep-alive', 'Content-Length': '1354'}
2023-09-24 00:32:05,824 ERROR   wandb-upload_0:917 [internal_api.py:upload_file():2196] upload_file response body: 
2023-09-24 00:32:08,265 DEBUG   HandlerThread:917 [handler.py:handle_request():144] handle_request: status_report
2023-09-24 00:32:08,819 INFO    cpu       :917 [interfaces.py:monitor():140] Process cpu has exited.
2023-09-24 00:32:08,820 DEBUG   SystemMonitor:917 [system_monitor.py:_start():159] Starting system metrics aggregation loop
2023-09-24 00:32:08,820 DEBUG   SystemMonitor:917 [system_monitor.py:_start():166] Finished system metrics aggregation loop
2023-09-24 00:32:08,821 DEBUG   SystemMonitor:917 [system_monitor.py:_start():170] Publishing last batch of metrics
2023-09-24 00:32:08,822 DEBUG   SenderThread:917 [sender.py:send():369] send: stats
2023-09-24 00:32:09,403 WARNING StreamThr :917 [internal.py:is_dead():414] Internal process exiting, parent pid 894 disappeared
2023-09-24 00:32:09,403 ERROR   StreamThr :917 [internal.py:wandb_internal():152] Internal process shutdown.
2023-09-24 00:32:09,821 INFO    HandlerThread:917 [handler.py:finish():854] shutting down handler
2023-09-24 00:32:09,822 INFO    WriterThread:917 [datastore.py:close():298] close: /mnt/d/PROJECTION/TianChi/STS-2D/wandb/run-20230924_003152-faesnysg/run-faesnysg.wandb
2023-09-24 00:32:09,822 INFO    SenderThread:917 [sender.py:finish():1526] shutting down sender
2023-09-24 00:32:09,824 INFO    HandlerThread:917 [system_monitor.py:finish():190] Stopping system monitor
2023-09-24 00:32:09,835 INFO    HandlerThread:917 [interfaces.py:finish():202] Joined cpu monitor
2023-09-24 00:32:09,836 INFO    HandlerThread:917 [interfaces.py:finish():202] Joined disk monitor
2023-09-24 00:32:09,837 INFO    HandlerThread:917 [interfaces.py:finish():202] Joined memory monitor
2023-09-24 00:32:09,839 INFO    HandlerThread:917 [interfaces.py:finish():202] Joined network monitor
2023-09-24 00:32:11,283 INFO    SenderThread:917 [dir_watcher.py:finish():359] shutting down directory watcher
2023-09-24 00:32:11,977 INFO    SenderThread:917 [dir_watcher.py:_on_file_modified():289] file/dir modified: /mnt/d/PROJECTION/TianChi/STS-2D/wandb/run-20230924_003152-faesnysg/files/output.log
2023-09-24 00:32:11,979 INFO    SenderThread:917 [dir_watcher.py:finish():389] scan: /mnt/d/PROJECTION/TianChi/STS-2D/wandb/run-20230924_003152-faesnysg/files
2023-09-24 00:32:11,980 INFO    SenderThread:917 [dir_watcher.py:finish():403] scan save: /mnt/d/PROJECTION/TianChi/STS-2D/wandb/run-20230924_003152-faesnysg/files/conda-environment.yaml conda-environment.yaml
2023-09-24 00:32:11,983 INFO    SenderThread:917 [dir_watcher.py:finish():403] scan save: /mnt/d/PROJECTION/TianChi/STS-2D/wandb/run-20230924_003152-faesnysg/files/config.yaml config.yaml
2023-09-24 00:32:11,986 INFO    SenderThread:917 [dir_watcher.py:finish():403] scan save: /mnt/d/PROJECTION/TianChi/STS-2D/wandb/run-20230924_003152-faesnysg/files/output.log output.log
2023-09-24 00:32:11,989 INFO    SenderThread:917 [dir_watcher.py:finish():403] scan save: /mnt/d/PROJECTION/TianChi/STS-2D/wandb/run-20230924_003152-faesnysg/files/requirements.txt requirements.txt
2023-09-24 00:32:11,991 INFO    SenderThread:917 [dir_watcher.py:finish():403] scan save: /mnt/d/PROJECTION/TianChi/STS-2D/wandb/run-20230924_003152-faesnysg/files/wandb-metadata.json wandb-metadata.json
2023-09-24 00:32:11,992 INFO    SenderThread:917 [dir_watcher.py:finish():403] scan save: /mnt/d/PROJECTION/TianChi/STS-2D/wandb/run-20230924_003152-faesnysg/files/wandb-summary.json wandb-summary.json
2023-09-24 00:32:11,994 INFO    SenderThread:917 [file_pusher.py:finish():159] shutting down file pusher
2023-09-24 00:32:11,995 INFO    SenderThread:917 [file_pusher.py:join():164] waiting for file pusher
