2023-09-24 00:23:45,821 INFO    StreamThr :438 [internal.py:wandb_internal():86] W&B internal server running at pid: 438, started at: 2023-09-24 00:23:45.820103
2023-09-24 00:23:45,822 DEBUG   HandlerThread:438 [handler.py:handle_request():144] handle_request: status
2023-09-24 00:23:45,824 INFO    WriterThread:438 [datastore.py:open_for_write():85] open: /mnt/d/PROJECTION/TianChi/STS-2D/wandb/run-20230924_002345-pu6ioma8/run-pu6ioma8.wandb
2023-09-24 00:23:45,832 DEBUG   SenderThread:438 [sender.py:send():369] send: header
2023-09-24 00:23:45,832 DEBUG   SenderThread:438 [sender.py:send():369] send: run
2023-09-24 00:23:47,539 DEBUG   HandlerThread:438 [handler.py:handle_request():144] handle_request: check_version
2023-09-24 00:23:47,542 INFO    SenderThread:438 [dir_watcher.py:__init__():211] watching files in: /mnt/d/PROJECTION/TianChi/STS-2D/wandb/run-20230924_002345-pu6ioma8/files
2023-09-24 00:23:47,542 INFO    SenderThread:438 [sender.py:_start_run_threads():1100] run started: pu6ioma8 with start time 1695486225.820945
2023-09-24 00:23:47,542 DEBUG   SenderThread:438 [sender.py:send_request():396] send_request: summary_record
2023-09-24 00:23:47,545 INFO    SenderThread:438 [sender.py:_save_file():1354] saving file wandb-summary.json with policy end
2023-09-24 00:23:47,547 DEBUG   SenderThread:438 [sender.py:send_request():396] send_request: check_version
2023-09-24 00:23:48,120 DEBUG   HandlerThread:438 [handler.py:handle_request():144] handle_request: run_start
2023-09-24 00:23:48,169 DEBUG   HandlerThread:438 [system_info.py:__init__():31] System info init
2023-09-24 00:23:48,170 DEBUG   HandlerThread:438 [system_info.py:__init__():46] System info init done
2023-09-24 00:23:48,170 INFO    HandlerThread:438 [system_monitor.py:start():181] Starting system monitor
2023-09-24 00:23:48,170 INFO    SystemMonitor:438 [system_monitor.py:_start():145] Starting system asset monitoring threads
2023-09-24 00:23:48,170 INFO    HandlerThread:438 [system_monitor.py:probe():201] Collecting system info
2023-09-24 00:23:48,172 INFO    SystemMonitor:438 [interfaces.py:start():190] Started cpu monitoring
2023-09-24 00:23:48,173 INFO    SystemMonitor:438 [interfaces.py:start():190] Started disk monitoring
2023-09-24 00:23:48,174 INFO    SystemMonitor:438 [interfaces.py:start():190] Started gpu monitoring
2023-09-24 00:23:48,175 INFO    SystemMonitor:438 [interfaces.py:start():190] Started memory monitoring
2023-09-24 00:23:48,175 INFO    SystemMonitor:438 [interfaces.py:start():190] Started network monitoring
2023-09-24 00:23:48,188 DEBUG   HandlerThread:438 [system_info.py:probe():195] Probing system
2023-09-24 00:23:48,222 DEBUG   HandlerThread:438 [gitlib.py:_init_repo():53] git repository is invalid
2023-09-24 00:23:48,222 DEBUG   HandlerThread:438 [system_info.py:probe():240] Probing system done
2023-09-24 00:23:48,223 DEBUG   HandlerThread:438 [system_monitor.py:probe():210] {'os': 'Linux-5.10.16.3-microsoft-standard-WSL2-x86_64-with-glibc2.35', 'python': '3.9.16', 'heartbeatAt': '2023-09-23T16:23:48.189016', 'startedAt': '2023-09-23T16:23:45.788043', 'docker': None, 'cuda': None, 'args': ('wandb', 'login'), 'state': 'running', 'program': '/mnt/d/PROJECTION/TianChi/STS-2D/train.py', 'codePath': 'train.py', 'host': 'DESKTOP-LT0ASMB', 'username': 'zy', 'executable': '/home/zy/anaconda3/envs/kaggle_torch/bin/python3', 'cpu_count': 3, 'cpu_count_logical': 5, 'cpu_freq': {'current': 3192.008, 'min': 0.0, 'max': 0.0}, 'cpu_freq_per_core': [{'current': 3192.008, 'min': 0.0, 'max': 0.0}, {'current': 3192.008, 'min': 0.0, 'max': 0.0}, {'current': 3192.008, 'min': 0.0, 'max': 0.0}, {'current': 3192.008, 'min': 0.0, 'max': 0.0}, {'current': 3192.008, 'min': 0.0, 'max': 0.0}], 'disk': {'total': 250.98248672485352, 'used': 63.609188079833984}, 'gpu': 'NVIDIA GeForce RTX 4090', 'gpu_count': 1, 'gpu_devices': [{'name': 'NVIDIA GeForce RTX 4090', 'memory_total': 25757220864}], 'memory': {'total': 24.93661880493164}}
2023-09-24 00:23:48,223 INFO    HandlerThread:438 [system_monitor.py:probe():211] Finished collecting system info
2023-09-24 00:23:48,223 INFO    HandlerThread:438 [system_monitor.py:probe():214] Publishing system info
2023-09-24 00:23:48,223 DEBUG   HandlerThread:438 [system_info.py:_save_pip():51] Saving list of pip packages installed into the current environment
2023-09-24 00:23:48,225 DEBUG   HandlerThread:438 [system_info.py:_save_pip():67] Saving pip packages done
2023-09-24 00:23:48,225 DEBUG   HandlerThread:438 [system_info.py:_save_conda():74] Saving list of conda packages installed into the current environment
2023-09-24 00:23:48,252 ERROR   HandlerThread:438 [system_info.py:_save_conda():85] Error saving conda packages: [Errno 2] No such file or directory: 'conda'
Traceback (most recent call last):
  File "/home/zy/anaconda3/envs/kaggle_torch/lib/python3.9/site-packages/wandb/sdk/internal/system/system_info.py", line 81, in _save_conda
    subprocess.call(
  File "/home/zy/anaconda3/envs/kaggle_torch/lib/python3.9/subprocess.py", line 349, in call
    with Popen(*popenargs, **kwargs) as p:
  File "/home/zy/anaconda3/envs/kaggle_torch/lib/python3.9/subprocess.py", line 951, in __init__
    self._execute_child(args, executable, preexec_fn, close_fds,
  File "/home/zy/anaconda3/envs/kaggle_torch/lib/python3.9/subprocess.py", line 1821, in _execute_child
    raise child_exception_type(errno_num, err_msg, err_filename)
FileNotFoundError: [Errno 2] No such file or directory: 'conda'
2023-09-24 00:23:48,256 DEBUG   HandlerThread:438 [system_info.py:_save_conda():86] Saving conda packages done
2023-09-24 00:23:48,259 INFO    HandlerThread:438 [system_monitor.py:probe():216] Finished publishing system info
2023-09-24 00:23:48,268 DEBUG   SenderThread:438 [sender.py:send():369] send: files
2023-09-24 00:23:48,268 INFO    SenderThread:438 [sender.py:_save_file():1354] saving file wandb-metadata.json with policy now
2023-09-24 00:23:48,274 DEBUG   HandlerThread:438 [handler.py:handle_request():144] handle_request: stop_status
2023-09-24 00:23:48,275 DEBUG   SenderThread:438 [sender.py:send_request():396] send_request: stop_status
2023-09-24 00:23:48,551 INFO    Thread-12 :438 [dir_watcher.py:_on_file_created():272] file/dir created: /mnt/d/PROJECTION/TianChi/STS-2D/wandb/run-20230924_002345-pu6ioma8/files/conda-environment.yaml
2023-09-24 00:23:48,552 INFO    Thread-12 :438 [dir_watcher.py:_on_file_created():272] file/dir created: /mnt/d/PROJECTION/TianChi/STS-2D/wandb/run-20230924_002345-pu6ioma8/files/wandb-metadata.json
2023-09-24 00:23:48,553 INFO    Thread-12 :438 [dir_watcher.py:_on_file_created():272] file/dir created: /mnt/d/PROJECTION/TianChi/STS-2D/wandb/run-20230924_002345-pu6ioma8/files/wandb-summary.json
2023-09-24 00:23:48,554 INFO    Thread-12 :438 [dir_watcher.py:_on_file_created():272] file/dir created: /mnt/d/PROJECTION/TianChi/STS-2D/wandb/run-20230924_002345-pu6ioma8/files/requirements.txt
2023-09-24 00:23:48,595 DEBUG   SenderThread:438 [sender.py:send():369] send: telemetry
2023-09-24 00:23:49,555 INFO    Thread-12 :438 [dir_watcher.py:_on_file_created():272] file/dir created: /mnt/d/PROJECTION/TianChi/STS-2D/wandb/run-20230924_002345-pu6ioma8/files/output.log
2023-09-24 00:23:49,605 ERROR   wandb-upload_0:438 [internal_api.py:upload_file():2192] upload_file exception https://storage.googleapis.com/wandb-production.appspot.com/zhuangy/STS-2D/pu6ioma8/wandb-metadata.json?Expires=1695572628&GoogleAccessId=gorilla-files-url-signer-man%40wandb-production.iam.gserviceaccount.com&Signature=wa93Nr319h2dOhd%2B1wld%2BCu3SKAlGBKlEV2D23Vp1QzySEpJ%2BAecLTR4WKTGC%2BmzZr4%2FsHeCjYWu5Ey7F%2BAIVeXfxG3Gz6wVWylAFppCC0gAqZ%2B%2Bw6ulAscxJv4k%2FfuZsnKqSd9%2BH3%2Fhd0omNOdu9rp8gIpBp1itpBdxk2ee5nzcUntfVTr8%2Bg470vWFIZQXduslv%2Bp9mSy5gMb053dRH8AWWumTiJQuPhprQyBKms%2Fs5UBGo62RA7P35i0bOrrBbBGFW6r54J3WKhNyjAR3wT1iY5qIOneQBL8sEdr96muOkVAfd%2Fn%2FMMLj0%2BiJMEb88cHstZeeQ3mAOYIhZzT0bQ%3D%3D: ('Connection aborted.', ConnectionResetError(104, 'Connection reset by peer'))
2023-09-24 00:23:49,605 ERROR   wandb-upload_0:438 [internal_api.py:upload_file():2194] upload_file request headers: {'User-Agent': 'python-requests/2.29.0', 'Accept-Encoding': 'gzip, deflate, br', 'Accept': '*/*', 'Connection': 'keep-alive', 'Content-Length': '1548'}
2023-09-24 00:23:49,605 ERROR   wandb-upload_0:438 [internal_api.py:upload_file():2196] upload_file response body: 
2023-09-24 00:23:51,035 DEBUG   HandlerThread:438 [handler.py:handle_request():144] handle_request: status_report
2023-09-24 00:23:51,042 ERROR   wandb-upload_0:438 [internal_api.py:upload_file():2192] upload_file exception https://storage.googleapis.com/wandb-production.appspot.com/zhuangy/STS-2D/pu6ioma8/wandb-metadata.json?Expires=1695572628&GoogleAccessId=gorilla-files-url-signer-man%40wandb-production.iam.gserviceaccount.com&Signature=wa93Nr319h2dOhd%2B1wld%2BCu3SKAlGBKlEV2D23Vp1QzySEpJ%2BAecLTR4WKTGC%2BmzZr4%2FsHeCjYWu5Ey7F%2BAIVeXfxG3Gz6wVWylAFppCC0gAqZ%2B%2Bw6ulAscxJv4k%2FfuZsnKqSd9%2BH3%2Fhd0omNOdu9rp8gIpBp1itpBdxk2ee5nzcUntfVTr8%2Bg470vWFIZQXduslv%2Bp9mSy5gMb053dRH8AWWumTiJQuPhprQyBKms%2Fs5UBGo62RA7P35i0bOrrBbBGFW6r54J3WKhNyjAR3wT1iY5qIOneQBL8sEdr96muOkVAfd%2Fn%2FMMLj0%2BiJMEb88cHstZeeQ3mAOYIhZzT0bQ%3D%3D: ('Connection aborted.', ConnectionResetError(104, 'Connection reset by peer'))
2023-09-24 00:23:51,042 ERROR   wandb-upload_0:438 [internal_api.py:upload_file():2194] upload_file request headers: {'User-Agent': 'python-requests/2.29.0', 'Accept-Encoding': 'gzip, deflate, br', 'Accept': '*/*', 'Connection': 'keep-alive', 'Content-Length': '1548'}
2023-09-24 00:23:51,043 ERROR   wandb-upload_0:438 [internal_api.py:upload_file():2196] upload_file response body: 
2023-09-24 00:23:51,565 INFO    Thread-12 :438 [dir_watcher.py:_on_file_modified():289] file/dir modified: /mnt/d/PROJECTION/TianChi/STS-2D/wandb/run-20230924_002345-pu6ioma8/files/output.log
2023-09-24 00:23:53,576 INFO    Thread-12 :438 [dir_watcher.py:_on_file_modified():289] file/dir modified: /mnt/d/PROJECTION/TianChi/STS-2D/wandb/run-20230924_002345-pu6ioma8/files/output.log
2023-09-24 00:23:53,960 ERROR   wandb-upload_0:438 [internal_api.py:upload_file():2192] upload_file exception https://storage.googleapis.com/wandb-production.appspot.com/zhuangy/STS-2D/pu6ioma8/wandb-metadata.json?Expires=1695572628&GoogleAccessId=gorilla-files-url-signer-man%40wandb-production.iam.gserviceaccount.com&Signature=wa93Nr319h2dOhd%2B1wld%2BCu3SKAlGBKlEV2D23Vp1QzySEpJ%2BAecLTR4WKTGC%2BmzZr4%2FsHeCjYWu5Ey7F%2BAIVeXfxG3Gz6wVWylAFppCC0gAqZ%2B%2Bw6ulAscxJv4k%2FfuZsnKqSd9%2BH3%2Fhd0omNOdu9rp8gIpBp1itpBdxk2ee5nzcUntfVTr8%2Bg470vWFIZQXduslv%2Bp9mSy5gMb053dRH8AWWumTiJQuPhprQyBKms%2Fs5UBGo62RA7P35i0bOrrBbBGFW6r54J3WKhNyjAR3wT1iY5qIOneQBL8sEdr96muOkVAfd%2Fn%2FMMLj0%2BiJMEb88cHstZeeQ3mAOYIhZzT0bQ%3D%3D: ('Connection aborted.', ConnectionResetError(104, 'Connection reset by peer'))
2023-09-24 00:23:53,961 ERROR   wandb-upload_0:438 [internal_api.py:upload_file():2194] upload_file request headers: {'User-Agent': 'python-requests/2.29.0', 'Accept-Encoding': 'gzip, deflate, br', 'Accept': '*/*', 'Connection': 'keep-alive', 'Content-Length': '1548'}
2023-09-24 00:23:53,961 ERROR   wandb-upload_0:438 [internal_api.py:upload_file():2196] upload_file response body: 
2023-09-24 00:23:53,961 INFO    wandb-upload_0:438 [retry.py:__call__():172] Retry attempt failed:
Traceback (most recent call last):
  File "/home/zy/anaconda3/envs/kaggle_torch/lib/python3.9/site-packages/urllib3/connectionpool.py", line 703, in urlopen
    httplib_response = self._make_request(
  File "/home/zy/anaconda3/envs/kaggle_torch/lib/python3.9/site-packages/urllib3/connectionpool.py", line 386, in _make_request
    self._validate_conn(conn)
  File "/home/zy/anaconda3/envs/kaggle_torch/lib/python3.9/site-packages/urllib3/connectionpool.py", line 1042, in _validate_conn
    conn.connect()
  File "/home/zy/anaconda3/envs/kaggle_torch/lib/python3.9/site-packages/urllib3/connection.py", line 419, in connect
    self.sock = ssl_wrap_socket(
  File "/home/zy/anaconda3/envs/kaggle_torch/lib/python3.9/site-packages/urllib3/util/ssl_.py", line 449, in ssl_wrap_socket
    ssl_sock = _ssl_wrap_socket_impl(
  File "/home/zy/anaconda3/envs/kaggle_torch/lib/python3.9/site-packages/urllib3/util/ssl_.py", line 493, in _ssl_wrap_socket_impl
    return ssl_context.wrap_socket(sock, server_hostname=server_hostname)
  File "/home/zy/anaconda3/envs/kaggle_torch/lib/python3.9/ssl.py", line 501, in wrap_socket
    return self.sslsocket_class._create(
  File "/home/zy/anaconda3/envs/kaggle_torch/lib/python3.9/ssl.py", line 1041, in _create
    self.do_handshake()
  File "/home/zy/anaconda3/envs/kaggle_torch/lib/python3.9/ssl.py", line 1310, in do_handshake
    self._sslobj.do_handshake()
ConnectionResetError: [Errno 104] Connection reset by peer

During handling of the above exception, another exception occurred:

Traceback (most recent call last):
  File "/home/zy/anaconda3/envs/kaggle_torch/lib/python3.9/site-packages/requests/adapters.py", line 487, in send
    resp = conn.urlopen(
  File "/home/zy/anaconda3/envs/kaggle_torch/lib/python3.9/site-packages/urllib3/connectionpool.py", line 787, in urlopen
    retries = retries.increment(
  File "/home/zy/anaconda3/envs/kaggle_torch/lib/python3.9/site-packages/urllib3/util/retry.py", line 550, in increment
    raise six.reraise(type(error), error, _stacktrace)
  File "/home/zy/anaconda3/envs/kaggle_torch/lib/python3.9/site-packages/urllib3/packages/six.py", line 769, in reraise
    raise value.with_traceback(tb)
  File "/home/zy/anaconda3/envs/kaggle_torch/lib/python3.9/site-packages/urllib3/connectionpool.py", line 703, in urlopen
    httplib_response = self._make_request(
  File "/home/zy/anaconda3/envs/kaggle_torch/lib/python3.9/site-packages/urllib3/connectionpool.py", line 386, in _make_request
    self._validate_conn(conn)
  File "/home/zy/anaconda3/envs/kaggle_torch/lib/python3.9/site-packages/urllib3/connectionpool.py", line 1042, in _validate_conn
    conn.connect()
  File "/home/zy/anaconda3/envs/kaggle_torch/lib/python3.9/site-packages/urllib3/connection.py", line 419, in connect
    self.sock = ssl_wrap_socket(
  File "/home/zy/anaconda3/envs/kaggle_torch/lib/python3.9/site-packages/urllib3/util/ssl_.py", line 449, in ssl_wrap_socket
    ssl_sock = _ssl_wrap_socket_impl(
  File "/home/zy/anaconda3/envs/kaggle_torch/lib/python3.9/site-packages/urllib3/util/ssl_.py", line 493, in _ssl_wrap_socket_impl
    return ssl_context.wrap_socket(sock, server_hostname=server_hostname)
  File "/home/zy/anaconda3/envs/kaggle_torch/lib/python3.9/ssl.py", line 501, in wrap_socket
    return self.sslsocket_class._create(
  File "/home/zy/anaconda3/envs/kaggle_torch/lib/python3.9/ssl.py", line 1041, in _create
    self.do_handshake()
  File "/home/zy/anaconda3/envs/kaggle_torch/lib/python3.9/ssl.py", line 1310, in do_handshake
    self._sslobj.do_handshake()
urllib3.exceptions.ProtocolError: ('Connection aborted.', ConnectionResetError(104, 'Connection reset by peer'))

During handling of the above exception, another exception occurred:

Traceback (most recent call last):
  File "/home/zy/anaconda3/envs/kaggle_torch/lib/python3.9/site-packages/wandb/sdk/internal/internal_api.py", line 2187, in upload_file
    response = self._upload_file_session.put(
  File "/home/zy/anaconda3/envs/kaggle_torch/lib/python3.9/site-packages/requests/sessions.py", line 647, in put
    return self.request("PUT", url, data=data, **kwargs)
  File "/home/zy/anaconda3/envs/kaggle_torch/lib/python3.9/site-packages/requests/sessions.py", line 587, in request
    resp = self.send(prep, **send_kwargs)
  File "/home/zy/anaconda3/envs/kaggle_torch/lib/python3.9/site-packages/requests/sessions.py", line 701, in send
    r = adapter.send(request, **kwargs)
  File "/home/zy/anaconda3/envs/kaggle_torch/lib/python3.9/site-packages/requests/adapters.py", line 502, in send
    raise ConnectionError(err, request=request)
requests.exceptions.ConnectionError: ('Connection aborted.', ConnectionResetError(104, 'Connection reset by peer'))

During handling of the above exception, another exception occurred:

Traceback (most recent call last):
  File "/home/zy/anaconda3/envs/kaggle_torch/lib/python3.9/site-packages/wandb/sdk/lib/retry.py", line 131, in __call__
    result = self._call_fn(*args, **kwargs)
  File "/home/zy/anaconda3/envs/kaggle_torch/lib/python3.9/site-packages/wandb/sdk/internal/internal_api.py", line 2216, in upload_file
    raise _e.with_traceback(sys.exc_info()[2])
  File "/home/zy/anaconda3/envs/kaggle_torch/lib/python3.9/site-packages/wandb/sdk/internal/internal_api.py", line 2187, in upload_file
    response = self._upload_file_session.put(
  File "/home/zy/anaconda3/envs/kaggle_torch/lib/python3.9/site-packages/requests/sessions.py", line 647, in put
    return self.request("PUT", url, data=data, **kwargs)
  File "/home/zy/anaconda3/envs/kaggle_torch/lib/python3.9/site-packages/requests/sessions.py", line 587, in request
    resp = self.send(prep, **send_kwargs)
  File "/home/zy/anaconda3/envs/kaggle_torch/lib/python3.9/site-packages/requests/sessions.py", line 701, in send
    r = adapter.send(request, **kwargs)
  File "/home/zy/anaconda3/envs/kaggle_torch/lib/python3.9/site-packages/requests/adapters.py", line 502, in send
    raise ConnectionError(err, request=request)
wandb.sdk.lib.retry.TransientError: None
2023-09-24 00:23:56,069 DEBUG   HandlerThread:438 [handler.py:handle_request():144] handle_request: status_report
2023-09-24 00:23:57,602 INFO    Thread-12 :438 [dir_watcher.py:_on_file_modified():289] file/dir modified: /mnt/d/PROJECTION/TianChi/STS-2D/wandb/run-20230924_002345-pu6ioma8/files/output.log
2023-09-24 00:23:58,840 ERROR   wandb-upload_0:438 [internal_api.py:upload_file():2192] upload_file exception https://storage.googleapis.com/wandb-production.appspot.com/zhuangy/STS-2D/pu6ioma8/wandb-metadata.json?Expires=1695572628&GoogleAccessId=gorilla-files-url-signer-man%40wandb-production.iam.gserviceaccount.com&Signature=wa93Nr319h2dOhd%2B1wld%2BCu3SKAlGBKlEV2D23Vp1QzySEpJ%2BAecLTR4WKTGC%2BmzZr4%2FsHeCjYWu5Ey7F%2BAIVeXfxG3Gz6wVWylAFppCC0gAqZ%2B%2Bw6ulAscxJv4k%2FfuZsnKqSd9%2BH3%2Fhd0omNOdu9rp8gIpBp1itpBdxk2ee5nzcUntfVTr8%2Bg470vWFIZQXduslv%2Bp9mSy5gMb053dRH8AWWumTiJQuPhprQyBKms%2Fs5UBGo62RA7P35i0bOrrBbBGFW6r54J3WKhNyjAR3wT1iY5qIOneQBL8sEdr96muOkVAfd%2Fn%2FMMLj0%2BiJMEb88cHstZeeQ3mAOYIhZzT0bQ%3D%3D: ('Connection aborted.', ConnectionResetError(104, 'Connection reset by peer'))
2023-09-24 00:23:58,840 ERROR   wandb-upload_0:438 [internal_api.py:upload_file():2194] upload_file request headers: {'User-Agent': 'python-requests/2.29.0', 'Accept-Encoding': 'gzip, deflate, br', 'Accept': '*/*', 'Connection': 'keep-alive', 'Content-Length': '1548'}
2023-09-24 00:23:58,840 ERROR   wandb-upload_0:438 [internal_api.py:upload_file():2196] upload_file response body: 
2023-09-24 00:23:59,613 INFO    Thread-12 :438 [dir_watcher.py:_on_file_modified():289] file/dir modified: /mnt/d/PROJECTION/TianChi/STS-2D/wandb/run-20230924_002345-pu6ioma8/files/output.log
2023-09-24 00:24:01,162 DEBUG   HandlerThread:438 [handler.py:handle_request():144] handle_request: status_report
2023-09-24 00:24:01,624 INFO    Thread-12 :438 [dir_watcher.py:_on_file_modified():289] file/dir modified: /mnt/d/PROJECTION/TianChi/STS-2D/wandb/run-20230924_002345-pu6ioma8/files/output.log
2023-09-24 00:24:03,632 INFO    Thread-12 :438 [dir_watcher.py:_on_file_modified():289] file/dir modified: /mnt/d/PROJECTION/TianChi/STS-2D/wandb/run-20230924_002345-pu6ioma8/files/output.log
2023-09-24 00:24:04,175 INFO    cpu       :438 [interfaces.py:monitor():140] Process cpu has exited.
2023-09-24 00:24:04,176 DEBUG   SystemMonitor:438 [system_monitor.py:_start():159] Starting system metrics aggregation loop
2023-09-24 00:24:04,176 DEBUG   SystemMonitor:438 [system_monitor.py:_start():166] Finished system metrics aggregation loop
2023-09-24 00:24:04,177 DEBUG   SystemMonitor:438 [system_monitor.py:_start():170] Publishing last batch of metrics
2023-09-24 00:24:04,178 DEBUG   SenderThread:438 [sender.py:send():369] send: stats
2023-09-24 00:24:05,667 INFO    Thread-12 :438 [dir_watcher.py:_on_file_modified():289] file/dir modified: /mnt/d/PROJECTION/TianChi/STS-2D/wandb/run-20230924_002345-pu6ioma8/files/output.log
2023-09-24 00:24:06,179 DEBUG   HandlerThread:438 [handler.py:handle_request():144] handle_request: status_report
2023-09-24 00:24:08,084 ERROR   wandb-upload_0:438 [internal_api.py:upload_file():2192] upload_file exception https://storage.googleapis.com/wandb-production.appspot.com/zhuangy/STS-2D/pu6ioma8/wandb-metadata.json?Expires=1695572628&GoogleAccessId=gorilla-files-url-signer-man%40wandb-production.iam.gserviceaccount.com&Signature=wa93Nr319h2dOhd%2B1wld%2BCu3SKAlGBKlEV2D23Vp1QzySEpJ%2BAecLTR4WKTGC%2BmzZr4%2FsHeCjYWu5Ey7F%2BAIVeXfxG3Gz6wVWylAFppCC0gAqZ%2B%2Bw6ulAscxJv4k%2FfuZsnKqSd9%2BH3%2Fhd0omNOdu9rp8gIpBp1itpBdxk2ee5nzcUntfVTr8%2Bg470vWFIZQXduslv%2Bp9mSy5gMb053dRH8AWWumTiJQuPhprQyBKms%2Fs5UBGo62RA7P35i0bOrrBbBGFW6r54J3WKhNyjAR3wT1iY5qIOneQBL8sEdr96muOkVAfd%2Fn%2FMMLj0%2BiJMEb88cHstZeeQ3mAOYIhZzT0bQ%3D%3D: ('Connection aborted.', ConnectionResetError(104, 'Connection reset by peer'))
2023-09-24 00:24:08,084 ERROR   wandb-upload_0:438 [internal_api.py:upload_file():2194] upload_file request headers: {'User-Agent': 'python-requests/2.29.0', 'Accept-Encoding': 'gzip, deflate, br', 'Accept': '*/*', 'Connection': 'keep-alive', 'Content-Length': '1548'}
2023-09-24 00:24:08,084 ERROR   wandb-upload_0:438 [internal_api.py:upload_file():2196] upload_file response body: 
2023-09-24 00:24:10,850 WARNING StreamThr :438 [internal.py:is_dead():414] Internal process exiting, parent pid 418 disappeared
2023-09-24 00:24:10,850 ERROR   StreamThr :438 [internal.py:wandb_internal():152] Internal process shutdown.
2023-09-24 00:24:11,180 INFO    SenderThread:438 [sender.py:finish():1526] shutting down sender
2023-09-24 00:24:11,180 INFO    HandlerThread:438 [handler.py:finish():854] shutting down handler
2023-09-24 00:24:11,180 INFO    HandlerThread:438 [system_monitor.py:finish():190] Stopping system monitor
2023-09-24 00:24:11,180 INFO    WriterThread:438 [datastore.py:close():298] close: /mnt/d/PROJECTION/TianChi/STS-2D/wandb/run-20230924_002345-pu6ioma8/run-pu6ioma8.wandb
2023-09-24 00:24:11,181 INFO    HandlerThread:438 [interfaces.py:finish():202] Joined cpu monitor
2023-09-24 00:24:11,181 INFO    HandlerThread:438 [interfaces.py:finish():202] Joined disk monitor
2023-09-24 00:24:11,182 INFO    HandlerThread:438 [interfaces.py:finish():202] Joined gpu monitor
2023-09-24 00:24:11,182 INFO    HandlerThread:438 [interfaces.py:finish():202] Joined memory monitor
2023-09-24 00:24:11,182 INFO    HandlerThread:438 [interfaces.py:finish():202] Joined network monitor
2023-09-24 00:24:13,217 INFO    SenderThread:438 [dir_watcher.py:finish():359] shutting down directory watcher
2023-09-24 00:24:13,678 INFO    SenderThread:438 [dir_watcher.py:_on_file_modified():289] file/dir modified: /mnt/d/PROJECTION/TianChi/STS-2D/wandb/run-20230924_002345-pu6ioma8/files/output.log
2023-09-24 00:24:13,679 INFO    SenderThread:438 [dir_watcher.py:finish():389] scan: /mnt/d/PROJECTION/TianChi/STS-2D/wandb/run-20230924_002345-pu6ioma8/files
2023-09-24 00:24:13,680 INFO    SenderThread:438 [dir_watcher.py:finish():403] scan save: /mnt/d/PROJECTION/TianChi/STS-2D/wandb/run-20230924_002345-pu6ioma8/files/conda-environment.yaml conda-environment.yaml
2023-09-24 00:24:13,683 INFO    SenderThread:438 [dir_watcher.py:finish():403] scan save: /mnt/d/PROJECTION/TianChi/STS-2D/wandb/run-20230924_002345-pu6ioma8/files/config.yaml config.yaml
2023-09-24 00:24:13,685 INFO    SenderThread:438 [dir_watcher.py:finish():403] scan save: /mnt/d/PROJECTION/TianChi/STS-2D/wandb/run-20230924_002345-pu6ioma8/files/output.log output.log
2023-09-24 00:24:13,688 INFO    SenderThread:438 [dir_watcher.py:finish():403] scan save: /mnt/d/PROJECTION/TianChi/STS-2D/wandb/run-20230924_002345-pu6ioma8/files/requirements.txt requirements.txt
2023-09-24 00:24:13,691 INFO    SenderThread:438 [dir_watcher.py:finish():403] scan save: /mnt/d/PROJECTION/TianChi/STS-2D/wandb/run-20230924_002345-pu6ioma8/files/wandb-metadata.json wandb-metadata.json
2023-09-24 00:24:13,691 INFO    SenderThread:438 [dir_watcher.py:finish():403] scan save: /mnt/d/PROJECTION/TianChi/STS-2D/wandb/run-20230924_002345-pu6ioma8/files/wandb-summary.json wandb-summary.json
2023-09-24 00:24:13,694 INFO    SenderThread:438 [file_pusher.py:finish():159] shutting down file pusher
2023-09-24 00:24:13,694 INFO    SenderThread:438 [file_pusher.py:join():164] waiting for file pusher
