Traceback (most recent call last):
  File "/home/zy/anaconda3/envs/kaggle_torch/lib/python3.9/site-packages/transformers/utils/hub.py", line 417, in cached_file
    resolved_file = hf_hub_download(
  File "/home/zy/anaconda3/envs/kaggle_torch/lib/python3.9/site-packages/huggingface_hub/utils/_validators.py", line 120, in _inner_fn
    return fn(*args, **kwargs)
  File "/home/zy/anaconda3/envs/kaggle_torch/lib/python3.9/site-packages/huggingface_hub/file_download.py", line 1291, in hf_hub_download
    raise LocalEntryNotFoundError(
huggingface_hub.utils._errors.LocalEntryNotFoundError: Connection error, and we cannot find the requested files in the disk cache. Please try again or make sure your Internet connection is on.
During handling of the above exception, another exception occurred:
Traceback (most recent call last):
  File "/mnt/d/PROJECTION/TianChi/STS-2D/train.py", line 178, in <module>
    model = STS2DModel(CFG, model_name=CFG.model_name)
  File "/mnt/d/PROJECTION/TianChi/STS-2D/models.py", line 32, in __init__
    self.model = SegformerForSemanticSegmentation.from_pretrained(
  File "/home/zy/anaconda3/envs/kaggle_torch/lib/python3.9/site-packages/transformers/modeling_utils.py", line 2251, in from_pretrained
    config, model_kwargs = cls.config_class.from_pretrained(
  File "/home/zy/anaconda3/envs/kaggle_torch/lib/python3.9/site-packages/transformers/configuration_utils.py", line 547, in from_pretrained
    config_dict, kwargs = cls.get_config_dict(pretrained_model_name_or_path, **kwargs)
  File "/home/zy/anaconda3/envs/kaggle_torch/lib/python3.9/site-packages/transformers/configuration_utils.py", line 574, in get_config_dict
    config_dict, kwargs = cls._get_config_dict(pretrained_model_name_or_path, **kwargs)
  File "/home/zy/anaconda3/envs/kaggle_torch/lib/python3.9/site-packages/transformers/configuration_utils.py", line 629, in _get_config_dict
    resolved_config_file = cached_file(
  File "/home/zy/anaconda3/envs/kaggle_torch/lib/python3.9/site-packages/transformers/utils/hub.py", line 452, in cached_file
    raise EnvironmentError(
OSError: We couldn't connect to 'https://huggingface.co' to load this file, couldn't find it in the cached files and it looks like nvidia/mit-b0 is not the path to a directory containing a file named config.json.
Checkout your internet connection or see how to run the library in offline mode at 'https://huggingface.co/docs/transformers/installation#offline-mode'.
using segformer for training.